<?xml version="1.0" encoding="utf-8"?>
<!--GLB Source: https://github.com/sapien-sim/xarm7/tree/master/sapien_xarm7/xarm_urdf/xarm_description/meshes-->
<robot name="xarm7_xhand_right">
  <link name="link_base">
    <inertial>
      <origin rpy="0 0 0" xyz="-0.021131 -0.0016302 0.056488"/>
      <mass value="0.88556"/>
      <inertia ixx="0.0030595" ixy="0.00012259" ixz="-0.00062705" iyy="0.0037783" iyz="0.00027023" izz="0.0020125"/>
    </inertial>
    <visual>
      <geometry>
        <mesh filename="../xarm7/meshes/visual/link_base.glb"/>
      </geometry>
      <origin rpy="0 0 0" xyz="0 0 0"/>
    </visual>
    <collision>
      <geometry>
        <mesh filename="../xarm7/meshes/collision/link_base.obj"/>
      </geometry>
      <origin rpy="0 0 0" xyz="0 0 0"/>
    </collision>
  </link>
  <link name="link1">
    <inertial>
      <origin rpy="0 0 0" xyz="-0.0002 0.02905 -0.01233"/>
      <mass value="2.382"/>
      <inertia ixx="0.0056905" ixy="-1.579e-05" ixz="5.125e-06" iyy="0.0049566" iyz="-0.000873378" izz="0.003316654"/>
    </inertial>
    <visual>
      <geometry>
        <mesh filename="../xarm7/meshes/visual/link1.glb"/>
      </geometry>
      <origin rpy="0 0 0" xyz="0 0 0"/>
    </visual>
    <collision>
      <geometry>
        <mesh filename="../xarm7/meshes/collision/link1.obj"/>
      </geometry>
      <origin rpy="0 0 0" xyz="0 0 0"/>
    </collision>
  </link>
  <joint name="joint1" type="revolute">
    <origin rpy="0 0 0" xyz="0 0 0.267"/>
    <parent link="link_base"/>
    <child link="link1"/>
    <axis xyz="0 0 1"/>
    <limit effort="50" lower="-6.28318530718" upper="6.28318530718" velocity="3.14"/>
    <dynamics damping="10" friction="1"/>
  </joint>
  <link name="link2">
    <inertial>
      <origin rpy="0 0 0" xyz="0.00022 -0.12856 0.01735"/>
      <mass value="1.869"/>
      <inertia ixx="0.0095989" ixy="1.541e-06" ixz="5.56e-06" iyy="0.00382472" iyz="-0.00317156" izz="0.007565669"/>
    </inertial>
    <visual>
      <geometry>
        <mesh filename="../xarm7/meshes/visual/link2.glb"/>
      </geometry>
      <origin rpy="0 0 0" xyz="0 0 0"/>
    </visual>
    <collision>
      <geometry>
        <mesh filename="../xarm7/meshes/collision/link2.obj"/>
      </geometry>
      <origin rpy="0 0 0" xyz="0 0 0"/>
    </collision>
  </link>
  <joint name="joint2" type="revolute">
    <origin rpy="-1.5708 0 0" xyz="0 0 0"/>
    <parent link="link1"/>
    <child link="link2"/>
    <axis xyz="0 0 1"/>
    <limit effort="50" lower="-2.059" upper="2.0944" velocity="3.14"/>
    <dynamics damping="10" friction="1"/>
  </joint>
  <link name="link3">
    <inertial>
      <origin rpy="0 0 0" xyz="0.0466 -0.02463 -0.00768"/>
      <mass value="1.6383"/>
      <inertia ixx="0.00310955" ixy="0.00030837" ixz="-0.00058453" iyy="0.00264483" iyz="0.000338893" izz="0.0026624"/>
    </inertial>
    <visual>
      <geometry>
        <mesh filename="../xarm7/meshes/visual/link3.glb"/>
      </geometry>
      <origin rpy="0 0 0" xyz="0 0 0"/>
    </visual>
    <collision>
      <geometry>
        <mesh filename="../xarm7/meshes/collision/link3.obj"/>
      </geometry>
      <origin rpy="0 0 0" xyz="0 0 0"/>
    </collision>
  </link>
  <joint name="joint3" type="revolute">
    <origin rpy="1.5708 0 0" xyz="0 -0.293 0"/>
    <parent link="link2"/>
    <child link="link3"/>
    <axis xyz="0 0 1"/>
    <limit effort="30" lower="-6.28318530718" upper="6.28318530718" velocity="3.14"/>
    <dynamics damping="5" friction="1"/>
  </joint>
  <link name="link4">
    <inertial>
      <origin rpy="0 0 0" xyz="0.07047 -0.11575 0.012"/>
      <mass value="1.7269"/>
      <inertia ixx="0.005889" ixy="0.00137112" ixz="0.00088143" iyy="0.00359703" iyz="-0.001762155" izz="0.00543244"/>
    </inertial>
    <visual>
      <geometry>
        <mesh filename="../xarm7/meshes/visual/link4.glb"/>
      </geometry>
      <origin rpy="0 0 0" xyz="0 0 0"/>
    </visual>
    <collision>
      <geometry>
        <mesh filename="../xarm7/meshes/collision/link4.obj"/>
      </geometry>
      <origin rpy="0 0 0" xyz="0 0 0"/>
    </collision>
  </link>
  <joint name="joint4" type="revolute">
    <origin rpy="1.5708 0 0" xyz="0.0525 0 0"/>
    <parent link="link3"/>
    <child link="link4"/>
    <axis xyz="0 0 1"/>
    <limit effort="30" lower="-0.19198" upper="3.927" velocity="3.14"/>
    <dynamics damping="5" friction="1"/>
  </joint>
  <link name="link5">
    <inertial>
      <origin rpy="0 0 0" xyz="-0.00032 0.01604 -0.026"/>
      <mass value="1.3203"/>
      <inertia ixx="0.00534665" ixy="1.5117e-05" ixz="-3.69e-07" iyy="0.0049779" iyz="-0.00022132" izz="0.0013624"/>
    </inertial>
    <visual>
      <geometry>
        <mesh filename="../xarm7/meshes/visual/link5.glb"/>
      </geometry>
      <origin rpy="0 0 0" xyz="0 0 0"/>
    </visual>
    <collision>
      <geometry>
        <mesh filename="../xarm7/meshes/collision/link5.obj"/>
      </geometry>
      <origin rpy="0 0 0" xyz="0 0 0"/>
    </collision>
  </link>
  <joint name="joint5" type="revolute">
    <origin rpy="1.5708 0 0" xyz="0.0775 -0.3425 0"/>
    <parent link="link4"/>
    <child link="link5"/>
    <axis xyz="0 0 1"/>
    <limit effort="30" lower="-6.28318530718" upper="6.28318530718" velocity="3.14"/>
    <dynamics damping="5" friction="1"/>
  </joint>
  <link name="link6">
    <inertial>
      <origin rpy="0 0 0" xyz="0.06469 0.03278 0.02141"/>
      <mass value="1.325"/>
      <inertia ixx="0.0014745" ixy="-0.000488" ixz="0.0002953" iyy="0.0019037" iyz="0.00014749" izz="0.0023652"/>
    </inertial>
    <visual>
      <geometry>
        <mesh filename="../xarm7/meshes/visual/link6.glb"/>
      </geometry>
      <origin rpy="0 0 0" xyz="0 0 0"/>
    </visual>
    <collision>
      <geometry>
        <mesh filename="../xarm7/meshes/collision/link6.obj"/>
      </geometry>
      <origin rpy="0 0 0" xyz="0 0 0"/>
    </collision>
  </link>
  <joint name="joint6" type="revolute">
    <origin rpy="1.5708 0 0" xyz="0 0 0"/>
    <parent link="link5"/>
    <child link="link6"/>
    <axis xyz="0 0 1"/>
    <limit effort="20" lower="-1.69297" upper="3.14159265359" velocity="3.14"/>
    <dynamics damping="2" friction="1"/>
  </joint>
  <link name="link7">
    <inertial>
      <origin rpy="0 0 0" xyz="0 -0.00677 -0.01098"/>
      <mass value="0.17"/>
      <inertia ixx="9.3e-05" ixy="-0.0" ixz="-0.0" iyy="5.87e-05" iyz="-3.6e-06" izz="0.000132"/>
    </inertial>
    <visual>
      <geometry>
        <mesh filename="../xarm7/meshes/visual/link7.glb"/>
      </geometry>
      <origin rpy="0 0 0" xyz="0 0 0"/>
    </visual>
    <collision>
      <geometry>
        <mesh filename="../xarm7/meshes/collision/link7.obj"/>
      </geometry>
      <origin rpy="0 0 0" xyz="0 0 0"/>
    </collision>
    <visual name="hand_mount">
      <origin rpy="1.57 0 0" xyz="0 0 0"/>
      <geometry>
        <mesh filename="meshes/xhand_xarm_mount.stl"/>
      </geometry>
    </visual>
    <collision name="hand_mount_collision">
      <origin rpy="0 0 0" xyz="0 0 0"/>
      <geometry>
        <cylinder radius="0.0365" length="0.007"/>
      </geometry>
    </collision>
  </link>
  <joint name="joint7" type="revolute">
    <origin rpy="-1.5708 0 0" xyz="0.076 0.097 0"/>
    <parent link="link6"/>
    <child link="link7"/>
    <axis xyz="0 0 1"/>
    <limit effort="20" lower="-6.28318530718" upper="6.28318530718" velocity="3.14"/>
    <dynamics damping="2" friction="1"/>
  </joint>

  <!-- Mount -->
  <joint name="joint_eef" type="fixed">
    <origin xyz="0 0 0.007" rpy="3.14 0 1.57"/>
    <parent link="link7"/>
    <child link="right_hand_link"/>
  </joint>

  <!-- Right Hand -->
  <link
    name="right_hand_link">
    <inertial>
      <origin
        xyz="-0.00366836214548078 0.0100351220466308 -0.0582695185384578"
        rpy="0 0 0" />
      <mass
        value="0.53903004" />
      <inertia
        ixx="0.0001"
        ixy="0.0"
        ixz="0.0"
        iyy="0.0001"
        iyz="0.0"
        izz="0.0001" />
    </inertial>
    <visual>
      <origin
        xyz="0 0 0"
        rpy="0 0 0" />
      <geometry>
        <mesh
          filename="../xhand/meshes/right_hand_link.STL" />
      </geometry>
      <material
        name="RAL_9005_Jet_Black">
        <color
          rgba="0.055 0.055 0.063 1.0" />
      </material>
    </visual>
    <collision>
      <origin
        xyz="0 0 0"
        rpy="0 0 0" />
      <geometry>
        <mesh
          filename="../xhand/meshes/right_hand_link.STL" />
      </geometry>
    </collision>
  </link>
  <link
    name="right_hand_ee_link">
    <inertial>
      <origin
        xyz="2.48510213245214E-19 -8.08284973285247E-18 0"
        rpy="0 0 0" />
      <mass
        value="0.00000565" />
      <inertia
        ixx="0.0001"
        ixy="0.0"
        ixz="0.0"
        iyy="0.0001"
        iyz="0.0"
        izz="0.0001" />
    </inertial>
    <visual>
      <origin
        xyz="0 0 0"
        rpy="0 0 0" />
      <geometry>
        <mesh
          filename="../xhand/meshes/right_hand_ee_link.STL" />
      </geometry>
      <material
        name="RAL_9005_Jet_Black">
        <color
          rgba="0.055 0.055 0.063 1.0" />
      </material>
    </visual>
    <collision>
      <origin
        xyz="0 0 0"
        rpy="0 0 0" />
      <geometry>
        <mesh
          filename="../xhand/meshes/right_hand_ee_link.STL" />
      </geometry>
    </collision>
  </link>
  <joint
    name="right_hand_ee_joint"
    type="fixed">
    <origin
      xyz="0 0 -0.065"
      rpy="0 0 0" />
    <parent
      link="right_hand_link" />
    <child
      link="right_hand_ee_link" />
    <axis
      xyz="0 0 0" />
    <dynamics
      damping="0"
      friction="0" />
  </joint>
  <link
    name="right_hand_back_link">
    <inertial>
      <origin
        xyz="-0.00149243508011096 -0.0140081556490721 0.000647100828228067"
        rpy="0 0 0" />
      <mass
        value="0.00000020" />
      <inertia
        ixx="0.0001"
        ixy="0.0"
        ixz="0.0"
        iyy="0.0001"
        iyz="0.0"
        izz="0.0001" />
    </inertial>
    <visual>
      <origin
        xyz="0 0 0"
        rpy="0 0 0" />
      <geometry>
        <mesh
          filename="../xhand/meshes/right_hand_back_link.STL" />
      </geometry>
      <material
        name="RAL_9003_Signal_White">
        <color
          rgba="0.941 0.941 0.941 1.0" />
      </material>
    </visual>
    <collision>
      <origin
        xyz="0 0 0"
        rpy="0 0 0" />
      <geometry>
        <mesh
          filename="../xhand/meshes/right_hand_back_link.STL" />
      </geometry>
    </collision>
  </link>
  <joint
    name="right_hand_back_joint"
    type="fixed">
    <origin
      xyz="0 0 -0.065"
      rpy="0 0 0" />
    <parent
      link="right_hand_link" />
    <child
      link="right_hand_back_link" />
    <axis
      xyz="0 0 0" />
    <dynamics
      damping="0"
      friction="0" />
  </joint>
  <link
    name="right_hand_thumb_bend_link">
    <inertial>
      <origin
        xyz="0.0144358799903648 -0.00116534489100676 -5.40665183231849E-05"
        rpy="0 0 0" />
      <mass
        value="0.01174632" />
      <inertia
        ixx="0.0001"
        ixy="0.0"
        ixz="0.0"
        iyy="0.0001"
        iyz="0.0"
        izz="0.0001" />
    </inertial>
    <visual>
      <origin
        xyz="0 0 0"
        rpy="0 0 0" />
      <geometry>
        <mesh
          filename="../xhand/meshes/right_hand_thumb_bend_link.STL" />
      </geometry>
      <material
        name="RAL_9005_Jet_Black">
        <color
          rgba="0.055 0.055 0.063 1.0" />
      </material>
    </visual>
    <collision>
      <origin
        xyz="0 0 0"
        rpy="0 0 0" />
      <geometry>
        <mesh
          filename="../xhand/meshes/right_hand_thumb_bend_link.STL" />
      </geometry>
    </collision>
  </link>
  <joint
    name="right_hand_thumb_bend_joint"
    type="revolute">
    <origin
      xyz="0.0228 0.0095 -0.0305"
      rpy="0 0 0" />
    <parent
      link="right_hand_link" />
    <child
      link="right_hand_thumb_bend_link" />
    <axis
      xyz="0 0 1" />
    <limit
      lower="0"
      upper="1.832"
      effort="1.1"
      velocity="8.63" />
    <dynamics
      damping="0"
      friction="0" />
  </joint>
  <link
    name="right_hand_thumb_rota_link1">
    <inertial>
      <origin
        xyz="0.0287681482733488 -0.00036176529547633 -0.00133929681686046"
        rpy="0 0 0" />
      <mass
        value="0.13266642" />
      <inertia
        ixx="0.0001"
        ixy="0.0"
        ixz="0.0"
        iyy="0.0001"
        iyz="0.0"
        izz="0.0001" />
    </inertial>
    <visual>
      <origin
        xyz="0 0 0"
        rpy="0 0 0" />
      <geometry>
        <mesh
          filename="../xhand/meshes/right_hand_thumb_rota_link1.STL" />
      </geometry>
      <material
        name="RAL_9005_Jet_Black">
        <color
          rgba="0.055 0.055 0.063 1.0" />
      </material>
    </visual>
    <collision>
      <origin
        xyz="0 0 0"
        rpy="0 0 0" />
      <geometry>
        <mesh
          filename="../xhand/meshes/right_hand_thumb_rota_link1.STL" />
      </geometry>
    </collision>
  </link>
  <joint
    name="right_hand_thumb_rota_joint1"
    type="revolute">
    <origin
      xyz="0.028599 0.0083177 0.00178"
      rpy="0.2618 0 0.0407" />
    <parent
      link="right_hand_thumb_bend_link" />
    <child
      link="right_hand_thumb_rota_link1" />
    <axis
      xyz="0 1 0" />
    <limit
      lower="-0.698"
      upper="1.745"
      effort="1.1"
      velocity="8.63" />
    <dynamics
      damping="0"
      friction="0" />
  </joint>
  <link
    name="right_hand_thumb_rotaback_link1">
    <inertial>
      <origin
        xyz="-0.0296289408411864 0.0014334239435258 0.00759117850867843"
        rpy="0 0 0" />
      <mass
        value="0.00000006" />
      <inertia
        ixx="0.0001"
        ixy="0.0"
        ixz="0.0"
        iyy="0.0001"
        iyz="0.0"
        izz="0.0001" />
    </inertial>
    <visual>
      <origin
        xyz="0 0 0"
        rpy="0 0 0" />
      <geometry>
        <mesh
          filename="../xhand/meshes/right_hand_thumb_rotaback_link1.STL" />
      </geometry>
      <material
        name="RAL_9003_Signal_White">
        <color
          rgba="0.941 0.941 0.941 1.0" />
      </material>
    </visual>
    <collision>
      <origin
        xyz="0 0 0"
        rpy="0 0 0" />
      <geometry>
        <mesh
          filename="../xhand/meshes/right_hand_thumb_rotaback_link1.STL" />
      </geometry>
    </collision>
  </link>
  <joint
    name="right_hand_thumb_rotaback_joint1"
    type="fixed">
    <origin
      xyz="0.0553000000000007 0 0"
      rpy="0 0 0" />
    <parent
      link="right_hand_thumb_rota_link1" />
    <child
      link="right_hand_thumb_rotaback_link1" />
    <axis
      xyz="0 0 0" />
    <dynamics
      damping="0"
      friction="0" />
  </joint>
  <link
    name="right_hand_thumb_rota_link2">
    <inertial>
      <origin
        xyz="0.0225340009927979 -0.000881600697645881 -0.000614548321208525"
        rpy="0 0 0" />
      <mass
        value="0.04336091" />
      <inertia
        ixx="0.0001"
        ixy="0.0"
        ixz="0.0"
        iyy="0.0001"
        iyz="0.0"
        izz="0.0001" />
    </inertial>
    <visual>
      <origin
        xyz="0 0 0"
        rpy="0 0 0" />
      <geometry>
        <mesh
          filename="../xhand/meshes/right_hand_thumb_rota_link2.STL" />
      </geometry>
      <material
        name="RAL_9005_Jet_Black">
        <color
          rgba="0.055 0.055 0.063 1.0" />
      </material>
    </visual>
    <collision>
      <origin
        xyz="0 0 0"
        rpy="0 0 0" />
      <geometry>
        <mesh
          filename="../xhand/meshes/right_hand_thumb_rota_link2.STL" />
      </geometry>
    </collision>
  </link>
  <joint
    name="right_hand_thumb_rota_joint2"
    type="revolute">
    <origin
      xyz="0.0553 0 0"
      rpy="0 0 0" />
    <parent
      link="right_hand_thumb_rota_link1" />
    <child
      link="right_hand_thumb_rota_link2" />
    <axis
      xyz="0 1 0" />
    <limit
      lower="0"
      upper="1.745"
      effort="0.4"
      velocity="14.38" />
    <dynamics
      damping="0"
      friction="0" />
  </joint>
  <link
    name="right_hand_thumb_rotaback_link2">
    <inertial>
      <origin
        xyz="-0.0258393463672562 -0.000532639688528967 0.00924631171368789"
        rpy="0 0 0" />
      <mass
        value="0.00000004" />
      <inertia
        ixx="0.0001"
        ixy="0.0"
        ixz="0.0"
        iyy="0.0001"
        iyz="0.0"
        izz="0.0001" />
    </inertial>
    <visual>
      <origin
        xyz="0 0 0"
        rpy="0 0 0" />
      <geometry>
        <mesh
          filename="../xhand/meshes/right_hand_thumb_rotaback_link2.STL" />
      </geometry>
      <material
        name="RAL_9003_Signal_White">
        <color
          rgba="0.941 0.941 0.941 1.0" />
      </material>
    </visual>
    <collision>
      <origin
        xyz="0 0 0"
        rpy="0 0 0" />
      <geometry>
        <mesh
          filename="../xhand/meshes/right_hand_thumb_rotaback_link2.STL" />
      </geometry>
    </collision>
  </link>
  <joint
    name="right_hand_thumb_rotaback_joint2"
    type="fixed">
    <origin
      xyz="0.0502276499414862 0 0"
      rpy="0 0 0" />
    <parent
      link="right_hand_thumb_rota_link2" />
    <child
      link="right_hand_thumb_rotaback_link2" />
    <axis
      xyz="0 0 0" />
    <dynamics
      damping="0"
      friction="0" />
  </joint>
  <link
    name="right_hand_thumb_rota_tip">
    <inertial>
      <origin
        xyz="8.32667268468867E-17 -8.67361737988404E-19 -5.55111512312578E-17"
        rpy="0 0 0" />
      <mass
        value="0.00000565" />
      <inertia
        ixx="0.0001"
        ixy="0.0"
        ixz="0.0"
        iyy="0.0001"
        iyz="0.0"
        izz="0.0001" />
    </inertial>
    <visual>
      <origin
        xyz="0 0 0"
        rpy="0 0 0" />
      <geometry>
        <mesh
          filename="../xhand/meshes/right_hand_thumb_rota_tip.STL" />
      </geometry>
      <material
        name="RAL_9005_Jet_Black">
        <color
          rgba="0.055 0.055 0.063 1.0" />
      </material>
    </visual>
    <collision>
      <origin
        xyz="0 0 0"
        rpy="0 0 0" />
      <geometry>
        <mesh
          filename="../xhand/meshes/right_hand_thumb_rota_tip.STL" />
      </geometry>
    </collision>
  </link>
  <joint
    name="right_hand_thumb_rota_joint3"
    type="fixed">
    <origin
      xyz="0.0502276499414862 0 0"
      rpy="0 0 0" />
    <parent
      link="right_hand_thumb_rota_link2" />
    <child
      link="right_hand_thumb_rota_tip" />
    <axis
      xyz="0 0 0" />
    <dynamics
      damping="0"
      friction="0" />
  </joint>
  <link
    name="right_hand_index_bend_link">
    <inertial>
      <origin
        xyz="0.000118997558760787 -0.000715851164577269 -0.0111903014853532"
        rpy="0 0 0" />
      <mass
        value="0.06910833" />
      <inertia
        ixx="0.0001"
        ixy="0.0"
        ixz="0.0"
        iyy="0.0001"
        iyz="0.0"
        izz="0.0001" />
    </inertial>
    <visual>
      <origin
        xyz="0 0 0"
        rpy="0 0 0" />
      <geometry>
        <mesh
          filename="../xhand/meshes/right_hand_index_bend_link.STL" />
      </geometry>
      <material
        name="RAL_9005_Jet_Black">
        <color
          rgba="0.055 0.055 0.063 1.0" />
      </material>
    </visual>
    <collision>
      <origin
        xyz="0 0 0"
        rpy="0 0 0" />
      <geometry>
        <mesh
          filename="../xhand/meshes/right_hand_index_bend_link.STL" />
      </geometry>
    </collision>
  </link>
  <joint
    name="right_hand_index_bend_joint"
    type="revolute">
    <origin
      xyz="0.0265 0.0065 -0.0899"
      rpy="0 0 0" />
    <parent
      link="right_hand_link" />
    <child
      link="right_hand_index_bend_link" />
    <axis
      xyz="0 -1 0" />
    <limit
      lower="-0.174"
      upper="0.174"
      effort="0.4"
      velocity="14.38" />
    <dynamics
      damping="0"
      friction="0" />
  </joint>
  <link
    name="right_hand_index_rota_link1">
    <inertial>
      <origin
        xyz="0.000133008106573459 0.000632930512954057 -0.0355868719939061"
        rpy="0 0 0" />
      <mass
        value="0.06298297" />
      <inertia
        ixx="0.00001738"
        ixy="0.00000000001"
        ixz="0.00000028"
        iyy="0.00001686"
        iyz="0.00000019"
        izz="0.0000032" />
    </inertial>
    <visual>
      <origin
        xyz="0 0 0"
        rpy="0 0 0" />
      <geometry>
        <mesh
          filename="../xhand/meshes/right_hand_index_rota_link1.STL" />
      </geometry>
      <material
        name="RAL_9005_Jet_Black">
        <color
          rgba="0.055 0.055 0.063 1" />
      </material>
    </visual>
    <collision>
      <origin
        xyz="0 0 0"
        rpy="0 0 0" />
      <geometry>
        <mesh
          filename="../xhand/meshes/right_hand_index_rota_link1.STL" />
      </geometry>
    </collision>
  </link>
  <joint
    name="right_hand_index_joint1"
    type="revolute">
    <origin
      xyz="0 0 -0.0178"
      rpy="0 0 0" />
    <parent
      link="right_hand_index_bend_link" />
    <child
      link="right_hand_index_rota_link1" />
    <axis
      xyz="1 0 0" />
    <limit
      lower="0"
      upper="1.919"
      effort="1.1"
      velocity="8.63" />
    <dynamics
      damping="0"
      friction="0" />
  </joint>
  <link
    name="right_hand_index_rotaback_link1">
    <inertial>
      <origin
        xyz="-0.000148035114615745 -0.0115948040516035 0.0241234077593065"
        rpy="0 0 0" />
      <mass
        value="0.00000002" />
      <inertia
        ixx="0.0001"
        ixy="0.0"
        ixz="0.0"
        iyy="0.0001"
        iyz="0.0"
        izz="0.0001" />
    </inertial>
    <visual>
      <origin
        xyz="0 0 0"
        rpy="0 0 0" />
      <geometry>
        <mesh
          filename="../xhand/meshes/right_hand_index_rotaback_link1.STL" />
      </geometry>
      <material
        name="RAL_9003_Signal_White">
        <color
          rgba="0.941 0.941 0.941 1" />
      </material>
    </visual>
    <collision>
      <origin
        xyz="0 0 0"
        rpy="0 0 0" />
      <geometry>
        <mesh
          filename="../xhand/meshes/right_hand_index_rotaback_link1.STL" />
      </geometry>
    </collision>
  </link>
  <joint
    name="right_hand_index_rotaback_joint1"
    type="fixed">
    <origin
      xyz="0 0 -0.0557999999999955"
      rpy="0 0 0" />
    <parent
      link="right_hand_index_rota_link1" />
    <child
      link="right_hand_index_rotaback_link1" />
    <axis
      xyz="0 0 0" />
    <dynamics
      damping="0"
      friction="0" />
  </joint>
  <link
    name="right_hand_index_rota_link2">
    <inertial>
      <origin
        xyz="-0.000248361661985549 0.00119905190206764 -0.0213789854478675"
        rpy="0 0 0" />
      <mass
        value="0.01588724" />
      <inertia
        ixx="0.00000277"
        ixy="0.00000000001"
        ixz="0.00000012"
        iyy="0.00000283"
        iyz="0.00000007"
        izz="0.00000085" />
    </inertial>
    <visual>
      <origin
        xyz="0 0 0"
        rpy="0 0 0" />
      <geometry>
        <mesh
          filename="../xhand/meshes/right_hand_index_rota_link2.STL" />
      </geometry>
      <material
        name="RAL_9005_Jet_Black">
        <color
          rgba="0.055 0.055 0.063 1" />
      </material>
    </visual>
    <collision>
      <origin
        xyz="0 0 0"
        rpy="0 0 0" />
      <geometry>
        <mesh
          filename="../xhand/meshes/right_hand_index_rota_link2.STL" />
      </geometry>
    </collision>
  </link>
  <joint
    name="right_hand_index_joint2"
    type="revolute">
    <origin
      xyz="0 0 -0.0558"
      rpy="0 0 0" />
    <parent
      link="right_hand_index_rota_link1" />
    <child
      link="right_hand_index_rota_link2" />
    <axis
      xyz="1 0 0" />
    <limit
      lower="0"
      upper="1.919"
      effort="0.4"
      velocity="14.38" />
    <dynamics
      damping="0"
      friction="0" />
  </joint>
  <link
    name="right_hand_index_rotaback_link2">
    <inertial>
      <origin
        xyz="0.00015795043863779 -0.00758843721876498 0.017665521085611"
        rpy="0 0 0" />
      <mass
        value="0.00000001" />
      <inertia
        ixx="0.0001"
        ixy="0.0"
        ixz="0.0"
        iyy="0.0001"
        iyz="0.0"
        izz="0.0001" />
    </inertial>
    <visual>
      <origin
        xyz="0 0 0"
        rpy="0 0 0" />
      <geometry>
        <mesh
          filename="../xhand/meshes/right_hand_index_rotaback_link2.STL" />
      </geometry>
      <material
        name="RAL_9003_Signal_White">
        <color
          rgba="0.941 0.941 0.941 1" />
      </material>
    </visual>
    <collision>
      <origin
        xyz="0 0 0"
        rpy="0 0 0" />
      <geometry>
        <mesh
          filename="../xhand/meshes/right_hand_index_rotaback_link2.STL" />
      </geometry>
    </collision>
  </link>
  <joint
    name="right_hand_index_rotaback_joint2"
    type="fixed">
    <origin
      xyz="0 0 -0.0422482924089416"
      rpy="0 0 0" />
    <parent
      link="right_hand_index_rota_link2" />
    <child
      link="right_hand_index_rotaback_link2" />
    <axis
      xyz="0 0 0" />
    <dynamics
      damping="0"
      friction="0" />
  </joint>
  <link
    name="right_hand_index_rota_tip">
    <inertial>
      <origin
        xyz="3.70675712346724E-14 8.65627014512427E-16 -8.32667268468867E-16"
        rpy="0 0 0" />
      <mass
        value="0.00000565" />
      <inertia
        ixx="0.0001"
        ixy="0.0"
        ixz="0.0"
        iyy="0.0001"
        iyz="0.0"
        izz="0.0001" />
    </inertial>
    <visual>
      <origin
        xyz="0 0 0"
        rpy="0 0 0" />
      <geometry>
        <mesh
          filename="../xhand/meshes/right_hand_index_rota_tip.STL" />
      </geometry>
      <material
        name="RAL_9005_Jet_Black">
        <color
          rgba="0.055 0.055 0.063 1" />
      </material>
    </visual>
    <collision>
      <origin
        xyz="0 0 0"
        rpy="0 0 0" />
      <geometry>
        <mesh
          filename="../xhand/meshes/right_hand_index_rota_tip.STL" />
      </geometry>
    </collision>
  </link>
  <joint
    name="right_hand_index_rota_joint3"
    type="fixed">
    <origin
      xyz="0 0 -0.0422482924089416"
      rpy="0 0 0" />
    <parent
      link="right_hand_index_rota_link2" />
    <child
      link="right_hand_index_rota_tip" />
    <axis
      xyz="0 0 0" />
    <dynamics
      damping="0"
      friction="0" />
  </joint>
  <link
    name="right_hand_mid_link1">
    <inertial>
      <origin
        xyz="3.58049083993136E-05 0.000530417592106078 -0.0332784671157236"
        rpy="0 0 0" />
      <mass
        value="0.06298297" />
      <inertia
        ixx="0.00001738"
        ixy="0.00000000001"
        ixz="0.00000028"
        iyy="0.00001686"
        iyz="0.00000019"
        izz="0.0000032" />
    </inertial>
    <visual>
      <origin
        xyz="0 0 0"
        rpy="0 0 0" />
      <geometry>
        <mesh
          filename="../xhand/meshes/right_hand_mid_link1.STL" />
      </geometry>
      <material
        name="RAL_9005_Jet_Black">
        <color
          rgba="0.055 0.055 0.063 1" />
      </material>
    </visual>
    <collision>
      <origin
        xyz="0 0 0"
        rpy="0 0 0" />
      <geometry>
        <mesh
          filename="../xhand/meshes/right_hand_mid_link1.STL" />
      </geometry>
    </collision>
  </link>
  <joint
    name="right_hand_mid_joint1"
    type="revolute">
    <origin
      xyz="0.004 0.0065 -0.1082"
      rpy="0 0 0" />
    <parent
      link="right_hand_link" />
    <child
      link="right_hand_mid_link1" />
    <axis
      xyz="1 0 0" />
    <limit
      lower="0"
      upper="1.919"
      effort="1.1"
      velocity="8.63" />
    <dynamics
      damping="0"
      friction="0" />
  </joint>
  <link
    name="right_hand_midback_link1">
    <inertial>
      <origin
        xyz="-0.000148035028410428 -0.0115948040189855 0.0241234086343709"
        rpy="0 0 0" />
      <mass
        value="0.00000002" />
      <inertia
        ixx="0.0001"
        ixy="0.0"
        ixz="0.0"
        iyy="0.0001"
        iyz="0.0"
        izz="0.0001" />
    </inertial>
    <visual>
      <origin
        xyz="0 0 0"
        rpy="0 0 0" />
      <geometry>
        <mesh
          filename="../xhand/meshes/right_hand_midback_link1.STL" />
      </geometry>
      <material
        name="RAL_9003_Signal_White">
        <color
          rgba="0.941 0.941 0.941 1" />
      </material>
    </visual>
    <collision>
      <origin
        xyz="0 0 0"
        rpy="0 0 0" />
      <geometry>
        <mesh
          filename="../xhand/meshes/right_hand_midback_link1.STL" />
      </geometry>
    </collision>
  </link>
  <joint
    name="right_hand_midback_joint1"
    type="fixed">
    <origin
      xyz="0 0 -0.0558"
      rpy="0 0 0" />
    <parent
      link="right_hand_mid_link1" />
    <child
      link="right_hand_midback_link1" />
    <axis
      xyz="0 0 0" />
    <dynamics
      damping="0"
      friction="0" />
  </joint>
  <link
    name="right_hand_mid_link2">
    <inertial>
      <origin
        xyz="-0.000248364601983051 0.00119905076177324 -0.0213789908421273"
        rpy="0 0 0" />
      <mass
        value="0.01624108" />
      <inertia
        ixx="0.00000281"
        ixy="0.00000000001"
        ixz="0.00000012"
        iyy="0.00000287"
        iyz="0.00000007"
        izz="0.00000086" />
    </inertial>
    <visual>
      <origin
        xyz="0 0 0"
        rpy="0 0 0" />
      <geometry>
        <mesh
          filename="../xhand/meshes/right_hand_mid_link2.STL" />
      </geometry>
      <material
        name="RAL_9005_Jet_Black">
        <color
          rgba="0.055 0.055 0.063 1" />
      </material>
    </visual>
    <collision>
      <origin
        xyz="0 0 0"
        rpy="0 0 0" />
      <geometry>
        <mesh
          filename="../xhand/meshes/right_hand_mid_link2.STL" />
      </geometry>
    </collision>
  </link>
  <joint
    name="right_hand_mid_joint2"
    type="revolute">
    <origin
      xyz="0 0 -0.0558"
      rpy="0 0 0" />
    <parent
      link="right_hand_mid_link1" />
    <child
      link="right_hand_mid_link2" />
    <axis
      xyz="1 0 0" />
    <limit
      lower="0"
      upper="1.919"
      effort="0.4"
      velocity="14.38" />
    <dynamics
      damping="0"
      friction="0" />
  </joint>
  <link
    name="right_hand_midback_link2">
    <inertial>
      <origin
        xyz="0.000157950438652398 -0.00758843721877396 0.0176655210856773"
        rpy="0 0 0" />
      <mass
        value="0.00000001" />
      <inertia
        ixx="0.0001"
        ixy="0.0"
        ixz="0.0"
        iyy="0.0001"
        iyz="0.0"
        izz="0.0001" />
    </inertial>
    <visual>
      <origin
        xyz="0 0 0"
        rpy="0 0 0" />
      <geometry>
        <mesh
          filename="../xhand/meshes/right_hand_midback_link2.STL" />
      </geometry>
      <material
        name="RAL_9003_Signal_White">
        <color
          rgba="0.941 0.941 0.941 1" />
      </material>
    </visual>
    <collision>
      <origin
        xyz="0 0 0"
        rpy="0 0 0" />
      <geometry>
        <mesh
          filename="../xhand/meshes/right_hand_midback_link2.STL" />
      </geometry>
    </collision>
  </link>
  <joint
    name="right_hand_midback_joint2"
    type="fixed">
    <origin
      xyz="0 0 -0.042248"
      rpy="0 0 0" />
    <parent
      link="right_hand_mid_link2" />
    <child
      link="right_hand_midback_link2" />
    <axis
      xyz="0 0 0" />
    <dynamics
      damping="0"
      friction="0" />
  </joint>
  <link
    name="right_hand_mid_tip">
    <inertial>
      <origin
        xyz="5.97126514900737E-14 5.86336534880161E-16 -8.32667268468867E-16"
        rpy="0 0 0" />
      <mass
        value="0.00000565" />
      <inertia
        ixx="0.0001"
        ixy="0.0"
        ixz="0.0"
        iyy="0.0001"
        iyz="0.0"
        izz="0.0001" />
    </inertial>
    <visual>
      <origin
        xyz="0 0 0"
        rpy="0 0 0" />
      <geometry>
        <mesh
          filename="../xhand/meshes/right_hand_mid_tip.STL" />
      </geometry>
      <material
        name="RAL_9005_Jet_Black">
        <color
          rgba="0.055 0.055 0.063 1" />
      </material>
    </visual>
    <collision>
      <origin
        xyz="0 0 0"
        rpy="0 0 0" />
      <geometry>
        <mesh
          filename="../xhand/meshes/right_hand_mid_tip.STL" />
      </geometry>
    </collision>
  </link>
  <joint
    name="right_hand_mid_joint3"
    type="fixed">
    <origin
      xyz="0 0 -0.0422482924089417"
      rpy="0 0 0" />
    <parent
      link="right_hand_mid_link2" />
    <child
      link="right_hand_mid_tip" />
    <axis
      xyz="0 0 0" />
    <dynamics
      damping="0"
      friction="0" />
  </joint>
  <link
    name="right_hand_ring_link1">
    <inertial>
      <origin
        xyz="3.58049083615322E-05 0.000530417592105594 -0.0332784671157224"
        rpy="0 0 0" />
      <mass
        value="0.06298297" />
      <inertia
        ixx="0.00001738"
        ixy="0.00000000001"
        ixz="0.00000028"
        iyy="0.00001686"
        iyz="0.00000019"
        izz="0.0000032" />
    </inertial>
    <visual>
      <origin
        xyz="0 0 0"
        rpy="0 0 0" />
      <geometry>
        <mesh
          filename="../xhand/meshes/right_hand_ring_link1.STL" />
      </geometry>
      <material
        name="RAL_9005_Jet_Black">
        <color
          rgba="0.055 0.055 0.063 1" />
      </material>
    </visual>
    <collision>
      <origin
        xyz="0 0 0"
        rpy="0 0 0" />
      <geometry>
        <mesh
          filename="../xhand/meshes/right_hand_ring_link1.STL" />
      </geometry>
    </collision>
  </link>
  <joint
    name="right_hand_ring_joint1"
    type="revolute">
    <origin
      xyz="-0.016 0.0065 -0.1052"
      rpy="0 0 0" />
    <parent
      link="right_hand_link" />
    <child
      link="right_hand_ring_link1" />
    <axis
      xyz="1 0 0" />
    <limit
      lower="0"
      upper="1.919"
      effort="1.1"
      velocity="8.63" />
    <dynamics
      damping="0"
      friction="0" />
  </joint>
  <link
    name="right_hand_ringback_link1">
    <inertial>
      <origin
        xyz="-0.000148033469798928 -0.0115948018402145 0.0241234223266379"
        rpy="0 0 0" />
      <mass
        value="0.00000002" />
      <inertia
        ixx="0.0001"
        ixy="0.0"
        ixz="0.0"
        iyy="0.0001"
        iyz="0.0"
        izz="0.0001" />
    </inertial>
    <visual>
      <origin
        xyz="0 0 0"
        rpy="0 0 0" />
      <geometry>
        <mesh
          filename="../xhand/meshes/right_hand_ringback_link1.STL" />
      </geometry>
      <material
        name="RAL_9003_Signal_White">
        <color
          rgba="0.941 0.941 0.941 1" />
      </material>
    </visual>
    <collision>
      <origin
        xyz="0 0 0"
        rpy="0 0 0" />
      <geometry>
        <mesh
          filename="../xhand/meshes/right_hand_ringback_link1.STL" />
      </geometry>
    </collision>
  </link>
  <joint
    name="right_hand_ringback_joint1"
    type="fixed">
    <origin
      xyz="0 0 -0.0558000000000002"
      rpy="0 0 0" />
    <parent
      link="right_hand_ring_link1" />
    <child
      link="right_hand_ringback_link1" />
    <axis
      xyz="0 0 0" />
    <dynamics
      damping="0"
      friction="0" />
  </joint>
  <link
    name="right_hand_ring_link2">
    <inertial>
      <origin
        xyz="-0.000248364602035429 0.00119905076177346 -0.0213789908421257"
        rpy="0 0 0" />
      <mass
        value="0.01624108" />
      <inertia
        ixx="0.00000281"
        ixy="0.00000000001"
        ixz="0.00000012"
        iyy="0.00000287"
        iyz="0.00000007"
        izz="0.00000086" />
    </inertial>
    <visual>
      <origin
        xyz="0 0 0"
        rpy="0 0 0" />
      <geometry>
        <mesh
          filename="../xhand/meshes/right_hand_ring_link2.STL" />
      </geometry>
      <material
        name="RAL_9005_Jet_Black">
        <color
          rgba="0.055 0.055 0.063 1" />
      </material>
    </visual>
    <collision>
      <origin
        xyz="0 0 0"
        rpy="0 0 0" />
      <geometry>
        <mesh
          filename="../xhand/meshes/right_hand_ring_link2.STL" />
      </geometry>
    </collision>
  </link>
  <joint
    name="right_hand_ring_joint2"
    type="revolute">
    <origin
      xyz="0 0 -0.0558"
      rpy="0 0 0" />
    <parent
      link="right_hand_ring_link1" />
    <child
      link="right_hand_ring_link2" />
    <axis
      xyz="1 0 0" />
    <limit
      lower="0"
      upper="1.919"
      effort="0.4"
      velocity="14.38" />
    <dynamics
      damping="0"
      friction="0" />
  </joint>
  <link
    name="right_hand_ringback_link2">
    <inertial>
      <origin
        xyz="0.000157950438638532 -0.00758843721878611 0.0176655210858899"
        rpy="0 0 0" />
      <mass
        value="0.00000001" />
      <inertia
        ixx="0.0001"
        ixy="0.0"
        ixz="0.0"
        iyy="0.0001"
        iyz="0.0"
        izz="0.0001" />
    </inertial>
    <visual>
      <origin
        xyz="0 0 0"
        rpy="0 0 0" />
      <geometry>
        <mesh
          filename="../xhand/meshes/right_hand_ringback_link2.STL" />
      </geometry>
      <material
        name="RAL_9003_Signal_White">
        <color
          rgba="0.941 0.941 0.941 1" />
      </material>
    </visual>
    <collision>
      <origin
        xyz="0 0 0"
        rpy="0 0 0" />
      <geometry>
        <mesh
          filename="../xhand/meshes/right_hand_ringback_link2.STL" />
      </geometry>
    </collision>
  </link>
  <joint
    name="right_hand_ringback_joint2"
    type="fixed">
    <origin
      xyz="0 0 -0.0422482924089403"
      rpy="0 0 0" />
    <parent
      link="right_hand_ring_link2" />
    <child
      link="right_hand_ringback_link2" />
    <axis
      xyz="0 0 0" />
    <dynamics
      damping="0"
      friction="0" />
  </joint>
  <link
    name="right_hand_ring_tip">
    <inertial>
      <origin
        xyz="1.22818422099158E-15 1.69135538907739E-16 0"
        rpy="0 0 0" />
      <mass
        value="0.00000565" />
      <inertia
        ixx="0.0001"
        ixy="0.0"
        ixz="0.0"
        iyy="0.0001"
        iyz="0.0"
        izz="0.0001" />
    </inertial>
    <visual>
      <origin
        xyz="0 0 0"
        rpy="0 0 0" />
      <geometry>
        <mesh
          filename="../xhand/meshes/right_hand_ring_tip.STL" />
      </geometry>
      <material
        name="RAL_9005_Jet_Black">
        <color
          rgba="0.055 0.055 0.063 1" />
      </material>
    </visual>
    <collision>
      <origin
        xyz="0 0 0"
        rpy="0 0 0" />
      <geometry>
        <mesh
          filename="../xhand/meshes/right_hand_ring_tip.STL" />
      </geometry>
    </collision>
  </link>
  <joint
    name="right_hand_ring_joint3"
    type="fixed">
    <origin
      xyz="0 0 -0.0422482924089403"
      rpy="0 0 0" />
    <parent
      link="right_hand_ring_link2" />
    <child
      link="right_hand_ring_tip" />
    <axis
      xyz="0 0 0" />
    <dynamics
      damping="0"
      friction="0" />
  </joint>
  <link
    name="right_hand_pinky_link1">
    <inertial>
      <origin
        xyz="3.58049083611298E-05 0.000530417592105422 -0.0332784671157224"
        rpy="0 0 0" />
      <mass
        value="0.06298297" />
      <inertia
        ixx="0.00001738"
        ixy="0.00000000001"
        ixz="0.00000028"
        iyy="0.00001686"
        iyz="0.00000019"
        izz="0.0000032" />
    </inertial>
    <visual>
      <origin
        xyz="0 0 0"
        rpy="0 0 0" />
      <geometry>
        <mesh
          filename="../xhand/meshes/right_hand_pinky_link1.STL" />
      </geometry>
      <material
        name="RAL_9005_Jet_Black">
        <color
          rgba="0.055 0.055 0.063 1" />
      </material>
    </visual>
    <collision>
      <origin
        xyz="0 0 0"
        rpy="0 0 0" />
      <geometry>
        <mesh
          filename="../xhand/meshes/right_hand_pinky_link1.STL" />
      </geometry>
    </collision>
  </link>
  <joint
    name="right_hand_pinky_joint1"
    type="revolute">
    <origin
      xyz="-0.036 0.0065 -0.1022"
      rpy="0 0 0" />
    <parent
      link="right_hand_link" />
    <child
      link="right_hand_pinky_link1" />
    <axis
      xyz="1 0 0" />
    <limit
      lower="0"
      upper="1.919"
      effort="1.1"
      velocity="8.63" />
    <dynamics
      damping="0"
      friction="0" />
  </joint>
  <link
    name="right_hand_pinkyback_link1">
    <inertial>
      <origin
        xyz="-0.000148034891232163 -0.0115948044185708 0.0241234089219646"
        rpy="0 0 0" />
      <mass
        value="0.00000002" />
      <inertia
        ixx="0.0001"
        ixy="0.0"
        ixz="0.0"
        iyy="0.0001"
        iyz="0.0"
        izz="0.0001" />
    </inertial>
    <visual>
      <origin
        xyz="0 0 0"
        rpy="0 0 0" />
      <geometry>
        <mesh
          filename="../xhand/meshes/right_hand_pinkyback_link1.STL" />
      </geometry>
      <material
        name="RAL_9003_Signal_White">
        <color
          rgba="0.941 0.941 0.941 1" />
      </material>
    </visual>
    <collision>
      <origin
        xyz="0 0 0"
        rpy="0 0 0" />
      <geometry>
        <mesh
          filename="../xhand/meshes/right_hand_pinkyback_link1.STL" />
      </geometry>
    </collision>
  </link>
  <joint
    name="right_hand_pinkyback_joint1"
    type="fixed">
    <origin
      xyz="0 0 -0.0558000000000001"
      rpy="0 0 0" />
    <parent
      link="right_hand_pinky_link1" />
    <child
      link="right_hand_pinkyback_link1" />
    <axis
      xyz="0 0 0" />
    <dynamics
      damping="0"
      friction="0" />
  </joint>
  <link
    name="right_hand_pinky_link2">
    <inertial>
      <origin
        xyz="-0.000248361662015334 0.0011990519020671 -0.0213789854478658"
        rpy="0 0 0" />
      <mass
        value="0.01624108" />
      <inertia
        ixx="0.00000281"
        ixy="0.00000000001"
        ixz="0.00000012"
        iyy="0.00000287"
        iyz="0.00000007"
        izz="0.00000086" />
    </inertial>
    <visual>
      <origin
        xyz="0 0 0"
        rpy="0 0 0" />
      <geometry>
        <mesh
          filename="../xhand/meshes/right_hand_pinky_link2.STL" />
      </geometry>
      <material
        name="RAL_9005_Jet_Black">
        <color
          rgba="0.055 0.055 0.063 1" />
      </material>
    </visual>
    <collision>
      <origin
        xyz="0 0 0"
        rpy="0 0 0" />
      <geometry>
        <mesh
          filename="../xhand/meshes/right_hand_pinky_link2.STL" />
      </geometry>
    </collision>
  </link>
  <joint
    name="right_hand_pinky_joint2"
    type="revolute">
    <origin
      xyz="0 0 -0.0558"
      rpy="0 0 0" />
    <parent
      link="right_hand_pinky_link1" />
    <child
      link="right_hand_pinky_link2" />
    <axis
      xyz="1 0 0" />
    <limit
      lower="0"
      upper="1.919"
      effort="1.4"
      velocity="14.38" />
    <dynamics
      damping="0"
      friction="0" />
  </joint>
  <link
    name="right_hand_pinkyback_link2">
    <inertial>
      <origin
        xyz="0.00015795043861809 -0.00758843721877113 0.0176655210856609"
        rpy="0 0 0" />
      <mass
        value="0.00000001" />
      <inertia
        ixx="0.0001"
        ixy="0.0"
        ixz="0.0"
        iyy="0.0001"
        iyz="0.0"
        izz="0.0001" />
    </inertial>
    <visual>
      <origin
        xyz="0 0 0"
        rpy="0 0 0" />
      <geometry>
        <mesh
          filename="../xhand/meshes/right_hand_pinkyback_link2.STL" />
      </geometry>
      <material
        name="RAL_9003_Signal_White">
        <color
          rgba="0.941 0.941 0.941 1" />
      </material>
    </visual>
    <collision>
      <origin
        xyz="0 0 0"
        rpy="0 0 0" />
      <geometry>
        <mesh
          filename="../xhand/meshes/right_hand_pinkyback_link2.STL" />
      </geometry>
    </collision>
  </link>
  <joint
    name="right_hand_pinkyback_joint2"
    type="fixed">
    <origin
      xyz="0 0 -0.0422482924089404"
      rpy="0 0 0" />
    <parent
      link="right_hand_pinky_link2" />
    <child
      link="right_hand_pinkyback_link2" />
    <axis
      xyz="0 0 0" />
    <dynamics
      damping="0"
      friction="0" />
  </joint>
  <link
    name="right_hand_pinky_tip">
    <inertial>
      <origin
        xyz="6.17561557447743E-16 8.67361737988404E-18 0"
        rpy="0 0 0" />
      <mass
        value="0.00000565" />
      <inertia
        ixx="0.0001"
        ixy="0.0"
        ixz="0.0"
        iyy="0.0001"
        iyz="0.0"
        izz="0.0001" />
    </inertial>
    <visual>
      <origin
        xyz="0 0 0"
        rpy="0 0 0" />
      <geometry>
        <mesh
          filename="../xhand/meshes/right_hand_pinky_tip.STL" />
      </geometry>
      <material
        name="RAL_9005_Jet_Black">
        <color
          rgba="0.055 0.055 0.063 1" />
      </material>
    </visual>
    <collision>
      <origin
        xyz="0 0 0"
        rpy="0 0 0" />
      <geometry>
        <mesh
          filename="../xhand/meshes/right_hand_pinky_tip.STL" />
      </geometry>
    </collision>
  </link>
  <joint
    name="right_hand_pinky_joint3"
    type="fixed">
    <origin
      xyz="0 0 -0.0422482924089404"
      rpy="0 0 0" />
    <parent
      link="right_hand_pinky_link2" />
    <child
      link="right_hand_pinky_tip" />
    <axis
      xyz="0 0 0" />
    <dynamics
      damping="0"
      friction="0" />
  </joint>



</robot>

